Workbook

Sheet OPT Plus Form 2B
I2: Republic of the Philippines
E3: Department of Health
E4: NATIONAL NUTRITION COUNCIL
E5: =IF(Barangays!$C$3="BARMM","Bangsamoro Autonomous Region in Muslim Mindanao",IF(Barangays!$C$3="CAR","Cordillera Administrative Region",IF(Barangays!$C$3="CARAGA","Region XIII - CARAGA",IF(Barangays!$C$3="NCR","National Capital Region",Barangays!$C$3)))) -> #REF!
A7: OPT Plus Form 2B. Summary Sheet of the Nutritional Status of 0-59 Month-Old Children in a Municipality or City
E9: =IF(AND(Barangays!$C$3="NCR",OR(Barangays!$C$4="MANILA",Barangays!$C$4="PASAY",Barangays!$C$4="CALOOCAN",Barangays!$C$4="QUEZON CITY")),"City District:",IF(AND(Barangays!$C$3="NCR",Barangays!$C$4<>"MANILA"),"",IF(ISNUMBER(SEARCH("CITY",Barangays!$C$4)),"",IF(Barangays!$B$4="","",IF(ISNUMBER(SEARCH("CITY",Barangays!$I$6)),"Province:","Province:"))))) -> #REF! | H9: =IF(ISNUMBER(SEARCH("CITY OF",Barangays!$C$4)),"",IF(Barangays!$C$4="MANILA",Barangays!$I$4,IF(OR(Barangays!$C$4="PASAY",Barangays!$C$4="CALOOCAN",Barangays!$C$4="QUEZON CITY"),Barangays!$I$4,IF(AND(Barangays!$C$3="NCR",OR(Barangays!$C$4<>"MANILA",Barangays!$C$4<>"PASAY",Barangays!$C$4<>"CALOOCAN",Barangays!$C$4<>"QUEZON CITY")),"",Barangays!$C$4)))) -> #REF! | O9: OPT Plus Coverage: | Q9: =IF(Barangays!$X$6="Weight + Length/Height",IFERROR(S14/J11,0),IFERROR(J14/Q11,0)) -> #REF! | T9: Total # Indigenous Preschool Children Measured:
F10: Total Population in | H10: =IF(OR(Barangays!$C$4="MANILA",Barangays!$C$4="PASAY",Barangays!$C$4="CALOOCAN",Barangays!$C$4="QUEZON CITY"),"City District:",IF(OR($A$11="Highly Urbanized City:",$A$11="Independent Component City:",$A$11="Component City:"),"City:",$A$11)) -> #REF! | J10: =$AC$17 | N10: Source: | P10: DOH - EB 2025 | T10: 0-59 mos: | V10: =Barangays!GA5 + Barangays!GC5 -> #REF! | W10: OPT PLUS | Y10: =IF(Barangays!$C$1="","",Barangays!$C$1) -> #REF!
A11: =IF(AND(Barangays!$C$3="NCR",Barangays!$C$4<>"PATEROS"),"Highly Urbanized City:",IF(ISNUMBER(SEARCH("CITY",Barangays!$C$4)),Barangays!$B$4,IF(Barangays!$C$4="SPECIAL GOVERNMENT UNIT","Cluster:",IF(ISNUMBER(SEARCH("CITY",Barangays!$I$4)),"Component City:","Municipality:")))) -> #REF! | B11: =IF(Barangays!$C$3="NCR",Barangays!$C$4,IF(ISNUMBER(SEARCH("CITY",Barangays!$C$4)),Barangays!$C$4,IF(ISNUMBER(SEARCH("CITY",Barangays!$I$4)),Barangays!$I$4,Barangays!$I$4))) -> #REF! | F11: Population of 0-59 months old in | H11: =H10 -> #REF! | J11: =$AD$17 | N11: Population of 6-59 months old in | P11: =H10 -> #REF! | Q11: =$AF$17
A12: PSGC: | B12: =$AE$17 | G12: =IF(Barangays!$X$6="MUAC", "", "Prevalence Rate MUW & SUW (Last OPT Plus):") -> #REF! | N12: =IF(Barangays!$X$6="MUAC", "", "Prevalence Rate MSt & SSt (Last OPT Plus):") -> #REF! | U12: Prevalence Rate MW/MAM & SW/SAM (Last OPT Plus):
B14: Total Boys: | D14: =Barangays!FZ5 -> #REF! | E14: Total Girls: | G14: =Barangays!GB5 -> #REF! | H14: Total MUAC: | J14: =Barangays!F5 -> #REF! | K14: Total WFA: | M14: =Barangays!C5 -> #REF! | N14: Total HFA: | P14: =Barangays!D5 -> #REF! | Q14: Total WFL/H: | S14: =Barangays!E5 -> #REF! | T14: Birth to 5 Years | V14: F1K | X14: # IP Children
B15: 0-5 Months | E15: 6-11 Months | H15: 12-23 Months | K15: 24-35 Months | N15: 36-47 Months | Q15: 48-59 Months | T15: 0-59 Months | V15: 0-23 Months | X15: Boys | Y15: Girls | Z15: Total
B16: Boys | C16: Girls | D16: Total | E16: Boys | F16: Girls | G16: Total | H16: Boys | I16: Girls | J16: Total | K16: Boys | L16: Girls | M16: Total | N16: Boys | O16: Girls | P16: Total | Q16: Boys | R16: Girls | S16: Total | T16: Total | U16: Prev | V16: Total | W16: Prev
A17: WFA - Normal | B17: =Barangays!CQ5 -> #REF! | C17: =Barangays!H5 -> #REF! | D17: =SUM(B17:C17) -> #REF! | E17: =Barangays!DC5 -> #REF! | F17: =Barangays!T5 -> #REF! | G17: =SUM(E17:F17) -> #REF! | H17: =Barangays!DR5 -> #REF! | I17: =Barangays!AI5 -> #REF! | J17: =SUM(H17:I17) -> #REF! | K17: =Barangays!EG5 -> #REF! | L17: =Barangays!AX5 -> #REF! | M17: =SUM(K17:L17) -> #REF! | N17: =Barangays!EV5 -> #REF! | O17: =Barangays!BM5 -> #REF! | P17: =SUM(N17:O17) -> #REF! | Q17: =Barangays!FK5 -> #REF! | R17: =Barangays!CB5 -> #REF! | S17: =SUM(Q17:R17) -> #REF! | T17: =D17+G17+J17+M17+P17+S17 -> #REF! | U17: =IF(M14=0,0,T17/M14) -> #REF! | V17: =D17+G17+J17 -> #REF! | W17: =IF(AC18=0,0,V17/AC18) -> #REF! | X17: =Barangays!HM5 -> #REF! | Y17: =Barangays!GX5 -> #REF! | Z17: =X17+Y17 -> #REF! | AC17: {=IFERROR(IF(Barangays!$MO$4=1,VLOOKUP($H$9,IF(Mun_City!$B$2:$B$1679=$B$11,Mun_City!$A$2:$G$1679,""),3,0),VLOOKUP(B11,IF(Mun_City!$B$2:$B$1679=H9,Mun_City!$A$2:$G$1679,""),3,0)),"")} | AD17: {=IFERROR(IF(Barangays!$MO$4=1,VLOOKUP($H$9,IF(Mun_City!$B$2:$B$1679=$B$11,Mun_City!$A$2:$G$1679,""),4,0),VLOOKUP(B11,IF(Mun_City!$B$2:$B$1679=H9,Mun_City!$A$2:$G$1679,""),4,0)),"")} | AE17: {=IFERROR(IF(Barangays!$MO$4=1,VLOOKUP($H$9,IF(Mun_City!$B$2:$B$1679=$B$11,Mun_City!$A$2:$G$1679,""),7,0),VLOOKUP(B11,IF(Mun_City!$B$2:$B$1679=H9,Mun_City!$A$2:$G$1679,""),7,0)),"")} | AF17: {=IFERROR(IF(Barangays!$MO$4=1,VLOOKUP($H$9,IF(Mun_City!$B$2:$B$1679=$B$11,Mun_City!$A$2:$G$1679,""),5,0),VLOOKUP(B11,IF(Mun_City!$B$2:$B$1679=H9,Mun_City!$A$2:$G$1679,""),5,0)),"")} | AG17: {=IFERROR(VLOOKUP($H$9,IF(Mun_City!$B$2:$B$1679=$B$11,Mun_City!$A$2:$H$1679,""),8,0),"")}
A18: WFA - Ob | B18: =IF(OR(Barangays!$X$6="MUAC", Barangays!$X$6=""), "", "No Obese/Overweight classification in the WFA. Following international standards, we use WL/H to classify overweight and obesity in children.") -> #REF! | AC18: =SUM(V17:V21) -> #REF! | AD18: =SUM(V22:V25) -> #REF! | AE18: =SUM(V26:V30) -> #REF! | AF18: =SUM(V31:V33) -> #REF!
A19: WFA - OW | AB19: IPs: | AD19: WFA: | AE19: M | AF19: =SUM(X17,X20,X21) -> #REF! | AG19: F | AH19: =SUM(Y17,Y20:Y21) -> #REF! | AI19: Total | AJ19: =SUM(Z17,Z20:Z21) -> #REF!
A20: WFA - MUW | B20: =Barangays!CS5 -> #REF! | C20: =Barangays!J5 -> #REF! | D20: =SUM(B20:C20) -> #REF! | E20: =Barangays!DE5 -> #REF! | F20: =Barangays!V5 -> #REF! | G20: =SUM(E20:F20) -> #REF! | H20: =Barangays!DT5 -> #REF! | I20: =Barangays!AK5 -> #REF! | J20: =SUM(H20:I20) -> #REF! | K20: =Barangays!EI5 -> #REF! | L20: =Barangays!AZ5 -> #REF! | M20: =SUM(K20:L20) -> #REF! | N20: =Barangays!EX5 -> #REF! | O20: =Barangays!BO5 -> #REF! | P20: =SUM(N20:O20) -> #REF! | Q20: =Barangays!FM5 -> #REF! | R20: =Barangays!CD5 -> #REF! | S20: =SUM(Q20:R20) -> #REF! | T20: =D20+G20+J20+M20+P20+S20 -> #REF! | U20: =IF(M14=0,0,T20/M14) -> #REF! | V20: =D20+G20+J20 -> #REF! | W20: =IF(AC18=0,0,V20/AC18) -> #REF! | X20: =Barangays!HN5 -> #REF! | Y20: =Barangays!GY5 -> #REF! | Z20: =X20+Y20 -> #REF! | AD20: HFA | AE20: M | AF20: =SUM(X22:X25) -> #REF! | AG20: F | AH20: =SUM(Y22:Y25) -> #REF! | AI20: Total | AJ20: =SUM(Z22:Z25) -> #REF!
A21: WFA - SUW | B21: =Barangays!CR5 -> #REF! | C21: =Barangays!I5 -> #REF! | D21: =SUM(B21:C21) -> #REF! | E21: =Barangays!DD5 -> #REF! | F21: =Barangays!U5 -> #REF! | G21: =SUM(E21:F21) -> #REF! | H21: =Barangays!DS5 -> #REF! | I21: =Barangays!AJ5 -> #REF! | J21: =SUM(H21:I21) -> #REF! | K21: =Barangays!EH5 -> #REF! | L21: =Barangays!AY5 -> #REF! | M21: =SUM(K21:L21) -> #REF! | N21: =Barangays!EW5 -> #REF! | O21: =Barangays!BN5 -> #REF! | P21: =SUM(N21:O21) -> #REF! | Q21: =Barangays!FL5 -> #REF! | R21: =Barangays!CC5 -> #REF! | S21: =SUM(Q21:R21) -> #REF! | T21: =D21+G21+J21+M21+P21+S21 -> #REF! | U21: =IF(M14=0,0,T21/M14) -> #REF! | V21: =D21+G21+J21 -> #REF! | W21: =IF(AC18=0,0,V21/AC18) -> #REF! | X21: =Barangays!HO5 -> #REF! | Y21: =Barangays!GZ5 -> #REF! | Z21: =X21+Y21 -> #REF! | AD21: WFL/H | AE21: M | AF21: =SUM(X26:X30) -> #REF! | AG21: M | AH21: =SUM(Y26:Y30) -> #REF! | AI21: Total | AJ21: =SUM(Z26:Z30) -> #REF!
A22: L/HFA - Normal | B22: =Barangays!CT5 -> #REF! | C22: =Barangays!K5 -> #REF! | D22: =SUM(B22:C22) -> #REF! | E22: =Barangays!DF5 -> #REF! | F22: =Barangays!W5 -> #REF! | G22: =SUM(E22:F22) -> #REF! | H22: =Barangays!DU5 -> #REF! | I22: =Barangays!AL5 -> #REF! | J22: =SUM(H22:I22) -> #REF! | K22: =Barangays!EJ5 -> #REF! | L22: =Barangays!BA5 -> #REF! | M22: =SUM(K22:L22) -> #REF! | N22: =Barangays!EY5 -> #REF! | O22: =Barangays!BP5 -> #REF! | P22: =SUM(N22:O22) -> #REF! | Q22: =Barangays!FN5 -> #REF! | R22: =Barangays!CE5 -> #REF! | S22: =SUM(Q22:R22) -> #REF! | T22: =D22+G22+J22+M22+P22+S22 -> #REF! | U22: =IF(P14=0,0,T22/P14) -> #REF! | V22: =D22+G22+J22 -> #REF! | W22: =IF(AD18=0,0,V22/AD18) -> #REF! | X22: =Barangays!HP5 -> #REF! | Y22: =Barangays!HA5 -> #REF! | Z22: =X22+Y22 -> #REF! | AC22: MUAC: | AD22: =SUM(T31:T33) -> #REF! | AE22: M | AF22: =SUM(X31:X33) -> #REF! | AG22: M | AH22: =SUM(Y31:Y33) -> #REF! | AI22: Total | AJ22: =SUM(Z31:Z33) -> #REF!
A23: L/HFA - Tall | B23: =Barangays!CW5 -> #REF! | C23: =Barangays!N5 -> #REF! | D23: =SUM(B23:C23) -> #REF! | E23: =Barangays!DI5 -> #REF! | F23: =Barangays!Z5 -> #REF! | G23: =SUM(E23:F23) -> #REF! | H23: =Barangays!DX5 -> #REF! | I23: =Barangays!AO5 -> #REF! | J23: =SUM(H23:I23) -> #REF! | K23: =Barangays!EM5 -> #REF! | L23: =Barangays!BD5 -> #REF! | M23: =SUM(K23:L23) -> #REF! | N23: =Barangays!FB5 -> #REF! | O23: =Barangays!BS5 -> #REF! | P23: =SUM(N23:O23) -> #REF! | Q23: =Barangays!FQ5 -> #REF! | R23: =Barangays!CH5 -> #REF! | S23: =SUM(Q23:R23) -> #REF! | T23: =D23+G23+J23+M23+P23+S23 -> #REF! | U23: =IF(P14=0,0,T23/P14) -> #REF! | V23: =D23+G23+J23 -> #REF! | W23: =IF(AD18=0,0,V23/AD18) -> #REF! | X23: =Barangays!HQ5 -> #REF! | Y23: =Barangays!HB5 -> #REF! | Z23: =X23+Y23 -> #REF!
A24: L/HFA - MSt | B24: =Barangays!CV5 -> #REF! | C24: =Barangays!M5 -> #REF! | D24: =SUM(B24:C24) -> #REF! | E24: =Barangays!DH5 -> #REF! | F24: =Barangays!Y5 -> #REF! | G24: =SUM(E24:F24) -> #REF! | H24: =Barangays!DW5 -> #REF! | I24: =Barangays!AN5 -> #REF! | J24: =SUM(H24:I24) -> #REF! | K24: =Barangays!EL5 -> #REF! | L24: =Barangays!BC5 -> #REF! | M24: =SUM(K24:L24) -> #REF! | N24: =Barangays!FA5 -> #REF! | O24: =Barangays!BR5 -> #REF! | P24: =SUM(N24:O24) -> #REF! | Q24: =Barangays!FP5 -> #REF! | R24: =Barangays!CG5 -> #REF! | S24: =SUM(Q24:R24) -> #REF! | T24: =D24+G24+J24+M24+P24+S24 -> #REF! | U24: =IF(P14=0,0,T24/P14) -> #REF! | V24: =D24+G24+J24 -> #REF! | W24: =IF(AD18=0,0,V24/AD18) -> #REF! | X24: =Barangays!HR5 -> #REF! | Y24: =Barangays!HC5 -> #REF! | Z24: =X24+Y24 -> #REF!
A25: L/HFA - SSt | B25: =Barangays!CU5 -> #REF! | C25: =Barangays!L5 -> #REF! | D25: =SUM(B25:C25) -> #REF! | E25: =Barangays!DG5 -> #REF! | F25: =Barangays!X5 -> #REF! | G25: =SUM(E25:F25) -> #REF! | H25: =Barangays!DV5 -> #REF! | I25: =Barangays!AM5 -> #REF! | J25: =SUM(H25:I25) -> #REF! | K25: =Barangays!EK5 -> #REF! | L25: =Barangays!BB5 -> #REF! | M25: =SUM(K25:L25) -> #REF! | N25: =Barangays!EZ5 -> #REF! | O25: =Barangays!BQ5 -> #REF! | P25: =SUM(N25:O25) -> #REF! | Q25: =Barangays!FO5 -> #REF! | R25: =Barangays!CF5 -> #REF! | S25: =SUM(Q25:R25) -> #REF! | T25: =D25+G25+J25+M25+P25+S25 -> #REF! | U25: =IF(P14=0,0,T25/P14) -> #REF! | V25: =D25+G25+J25 -> #REF! | W25: =IF(AD18=0,0,V25/AD18) -> #REF! | X25: =Barangays!HS5 -> #REF! | Y25: =Barangays!HD5 -> #REF! | Z25: =X25+Y25 -> #REF!
A26: WFL/H - Normal | B26: =Barangays!CX5 -> #REF! | C26: =Barangays!O5 -> #REF! | D26: =SUM(B26:C26) -> #REF! | E26: =Barangays!DJ5 -> #REF! | F26: =Barangays!AA5 -> #REF! | G26: =SUM(E26:F26) -> #REF! | H26: =Barangays!DY5 -> #REF! | I26: =Barangays!AP5 -> #REF! | J26: =SUM(H26:I26) -> #REF! | K26: =Barangays!EN5 -> #REF! | L26: =Barangays!BE5 -> #REF! | M26: =SUM(K26:L26) -> #REF! | N26: =Barangays!FC5 -> #REF! | O26: =Barangays!BT5 -> #REF! | P26: =SUM(N26:O26) -> #REF! | Q26: =Barangays!FR5 -> #REF! | R26: =Barangays!CI5 -> #REF! | S26: =SUM(Q26:R26) -> #REF! | T26: =D26+G26+J26+M26+P26+S26 -> #REF! | U26: =IF(S14=0,0,T26/S14) -> #REF! | V26: =D26+G26+J26 -> #REF! | W26: =IF(AE18=0,0,V26/AE18) -> #REF! | X26: =Barangays!HT5 -> #REF! | Y26: =Barangays!HE5 -> #REF! | Z26: =X26+Y26 -> #REF!
A27: WFL/H - OW | B27: =Barangays!CY5 -> #REF! | C27: =Barangays!P5 -> #REF! | D27: =SUM(B27:C27) -> #REF! | E27: =Barangays!DK5 -> #REF! | F27: =Barangays!AB5 -> #REF! | G27: =SUM(E27:F27) -> #REF! | H27: =Barangays!DZ5 -> #REF! | I27: =Barangays!AQ5 -> #REF! | J27: =SUM(H27:I27) -> #REF! | K27: =Barangays!EO5 -> #REF! | L27: =Barangays!BF5 -> #REF! | M27: =SUM(K27:L27) -> #REF! | N27: =Barangays!FD5 -> #REF! | O27: =Barangays!BU5 -> #REF! | P27: =SUM(N27:O27) -> #REF! | Q27: =Barangays!FS5 -> #REF! | R27: =Barangays!CJ5 -> #REF! | S27: =SUM(Q27:R27) -> #REF! | T27: =D27+G27+J27+M27+P27+S27 -> #REF! | U27: =IF(S14=0,0,T27/S14) -> #REF! | V27: =D27+G27+J27 -> #REF! | W27: =IF(AE18=0,0,V27/AE18) -> #REF! | X27: =Barangays!HU5 -> #REF! | Y27: =Barangays!HF5 -> #REF! | Z27: =X27+Y27 -> #REF!
A28: WFL/H - Ob | B28: =Barangays!CZ5 -> #REF! | C28: =Barangays!Q5 -> #REF! | D28: =SUM(B28:C28) -> #REF! | E28: =Barangays!DL5 -> #REF! | F28: =Barangays!AC5 -> #REF! | G28: =SUM(E28:F28) -> #REF! | H28: =Barangays!EA5 -> #REF! | I28: =Barangays!AR5 -> #REF! | J28: =SUM(H28:I28) -> #REF! | K28: =Barangays!EP5 -> #REF! | L28: =Barangays!BG5 -> #REF! | M28: =SUM(K28:L28) -> #REF! | N28: =Barangays!FE5 -> #REF! | O28: =Barangays!BV5 -> #REF! | P28: =SUM(N28:O28) -> #REF! | Q28: =Barangays!FT5 -> #REF! | R28: =Barangays!CK5 -> #REF! | S28: =SUM(Q28:R28) -> #REF! | T28: =D28+G28+J28+M28+P28+S28 -> #REF! | U28: =IF(S14=0,0,T28/S14) -> #REF! | V28: =D28+G28+J28 -> #REF! | W28: =IF(AE18=0,0,V28/AE18) -> #REF! | X28: =Barangays!HV5 -> #REF! | Y28: =Barangays!HG5 -> #REF! | Z28: =X28+Y28 -> #REF!
A29: WFL/H - MW/MAM | B29: =Barangays!DB5 -> #REF! | C29: =Barangays!S5 -> #REF! | D29: =SUM(B29:C29) -> #REF! | E29: =Barangays!DN5 -> #REF! | F29: =Barangays!AE5 -> #REF! | G29: =SUM(E29:F29) -> #REF! | H29: =Barangays!EC5 -> #REF! | I29: =Barangays!AT5 -> #REF! | J29: =SUM(H29:I29) -> #REF! | K29: =Barangays!ER5 -> #REF! | L29: =Barangays!BI5 -> #REF! | M29: =SUM(K29:L29) -> #REF! | N29: =Barangays!FG5 -> #REF! | O29: =Barangays!BX5 -> #REF! | P29: =SUM(N29:O29) -> #REF! | Q29: =Barangays!FV5 -> #REF! | R29: =Barangays!CM5 -> #REF! | S29: =SUM(Q29:R29) -> #REF! | T29: =D29+G29+J29+M29+P29+S29 -> #REF! | U29: =IF(S14=0,0,T29/S14) -> #REF! | V29: =D29+G29+J29 -> #REF! | W29: =IF(AE18=0,0,V29/AE18) -> #REF! | X29: =Barangays!HW5 -> #REF! | Y29: =Barangays!HH5 -> #REF! | Z29: =X29+Y29 -> #REF!
A30: WFL/H - SW/SAM | B30: =Barangays!DA5 -> #REF! | C30: =Barangays!R5 -> #REF! | D30: =SUM(B30:C30) -> #REF! | E30: =Barangays!DM5 -> #REF! | F30: =Barangays!AD5 -> #REF! | G30: =SUM(E30:F30) -> #REF! | H30: =Barangays!EB5 -> #REF! | I30: =Barangays!AS5 -> #REF! | J30: =SUM(H30:I30) -> #REF! | K30: =Barangays!EQ5 -> #REF! | L30: =Barangays!BH5 -> #REF! | M30: =SUM(K30:L30) -> #REF! | N30: =Barangays!FF5 -> #REF! | O30: =Barangays!BW5 -> #REF! | P30: =SUM(N30:O30) -> #REF! | Q30: =Barangays!FU5 -> #REF! | R30: =Barangays!CL5 -> #REF! | S30: =SUM(Q30:R30) -> #REF! | T30: =D30+G30+J30+M30+P30+S30 -> #REF! | U30: =IF(S14=0,0,T30/S14) -> #REF! | V30: =D30+G30+J30 -> #REF! | W30: =IF(AE18=0,0,V30/AE18) -> #REF! | X30: =Barangays!HX5 -> #REF! | Y30: =Barangays!HI5 -> #REF! | Z30: =X30+Y30 -> #REF!
A31: MUAC - Normal | E31: =Barangays!DO5 -> #REF! | F31: =Barangays!AF5 -> #REF! | G31: =SUM(E31:F31) -> #REF! | H31: =Barangays!ED5 -> #REF! | I31: =Barangays!AU5 -> #REF! | J31: =SUM(H31:I31) -> #REF! | K31: =Barangays!ES5 -> #REF! | L31: =Barangays!BJ5 -> #REF! | M31: =SUM(K31:L31) -> #REF! | N31: =Barangays!FH5 -> #REF! | O31: =Barangays!BY5 -> #REF! | P31: =SUM(N31:O31) -> #REF! | Q31: =Barangays!FW5 -> #REF! | R31: =Barangays!CN5 -> #REF! | S31: =SUM(Q31:R31) -> #REF! | T31: =D31+G31+J31+M31+P31+S31 -> #REF! | U31: =IF(J14=0,0,T31/J14) -> #REF! | V31: =G31+J31 -> #REF! | W31: =IF(AF18=0,0,V31/AF18) -> #REF! | X31: =Barangays!HY5 -> #REF! | Y31: =Barangays!HJ5 -> #REF! | Z31: =X31+Y31 -> #REF!
A32: MUAC - MW/MAM | E32: =Barangays!DP5 -> #REF! | F32: =Barangays!AG5 -> #REF! | G32: =SUM(E32:F32) -> #REF! | H32: =Barangays!EE5 -> #REF! | I32: =Barangays!AV5 -> #REF! | J32: =SUM(H32:I32) -> #REF! | K32: =Barangays!ET5 -> #REF! | L32: =Barangays!BK5 -> #REF! | M32: =SUM(K32:L32) -> #REF! | N32: =Barangays!FI5 -> #REF! | O32: =Barangays!BZ5 -> #REF! | P32: =SUM(N32:O32) -> #REF! | Q32: =Barangays!FX5 -> #REF! | R32: =Barangays!CO5 -> #REF! | S32: =SUM(Q32:R32) -> #REF! | T32: =D32+G32+J32+M32+P32+S32 -> #REF! | U32: =IF(J14=0,0,T32/J14) -> #REF! | V32: =G32+J32 -> #REF! | W32: =IF(AF18=0,0,V32/AF18) -> #REF! | X32: =Barangays!HZ5 -> #REF! | Y32: =Barangays!HK5 -> #REF! | Z32: =X32+Y32 -> #REF!
A33: MUAC - SW/SAM | E33: =Barangays!DQ5 -> #REF! | F33: =Barangays!AH5 -> #REF! | G33: =SUM(E33:F33) -> #REF! | H33: =Barangays!EF5 -> #REF! | I33: =Barangays!AW5 -> #REF! | J33: =SUM(H33:I33) -> #REF! | K33: =Barangays!EU5 -> #REF! | L33: =Barangays!BL5 -> #REF! | M33: =SUM(K33:L33) -> #REF! | N33: =Barangays!FJ5 -> #REF! | O33: =Barangays!CA5 -> #REF! | P33: =SUM(N33:O33) -> #REF! | Q33: =Barangays!FY5 -> #REF! | R33: =Barangays!CP5 -> #REF! | S33: =SUM(Q33:R33) -> #REF! | T33: =D33+G33+J33+M33+P33+S33 -> #REF! | U33: =IF(J14=0,0,T33/J14) -> #REF! | V33: =G33+J33 -> #REF! | W33: =IF(AF18=0,0,V33/AF18) -> #REF! | X33: =Barangays!IA5 -> #REF! | Y33: =Barangays!HL5 -> #REF! | Z33: =X33+Y33 -> #REF!
A34: Total (WFA) | B34: =SUM(B17:B21) -> #REF! | C34: =SUM(C17:C21) -> #REF! | D34: =SUM(D17:D21) -> #REF! | E34: =SUM(E17:E21) -> #REF! | F34: =SUM(F17:F21) -> #REF! | G34: =SUM(G17:G21) -> #REF! | H34: =SUM(H17:H21) -> #REF! | I34: =SUM(I17:I21) -> #REF! | ... S34: =SUM(S17:S21) -> #REF!
A35: Summary of Children covered by e-OPT Plus | I35: Mothers/Caregivers Summary | T35: Data Inaccuracy
A36: # Children 0-59 mos. who are Wasted and/or Stunted : | H36: =Barangays!GH5 -> #REF! | I36: Total Number of M/Cs of children 0-59 mos. old: | S36: =Barangays!GR5 -> #REF! | T36: # Children with names and birthdate repeated: | Z36: =Barangays!IB5 -> #REF!
A37: # Children 24-59 mos. who are Wasted and/or Stunted: | H37: =Barangays!GI5 -> #REF! | I37: # M/Cs of 0-59 mos children affected by Wasting and/or Stunting: | S37: =Barangays!GS5 -> #REF! | T37: # Children with missing information: | Z37: =Barangays!IE5 -> #REF!
A38: # Children 0-59 mos. who are Overweight/Obesity: | H38: =Barangays!GJ5 -> #REF! | I38: # M/Cs of 0-59 mos. children who are Overweight/Obesity: | S38: =Barangays!GT5 -> #REF! | T38: # Children with no name of parents/address: | Z38: =Barangays!IH5 -> #REF!
A39: Total Number of Children 0-23 mos. old: | H39: =Barangays!GK5 -> #REF! | I39: Total Number of M/Cs of children 0-23 mos. old: | S39: =Barangays!GU5 -> #REF! | T39: # Children with no sex data: | Z39: =Barangays!IG5 -> #REF!
A40: # Children 0-23 mos. who are Wasted and/or Stunted: | H40: =Barangays!GL5 -> #REF! | I40: # M/Cs of 0-23 mos children affected by Wasting and/or Stunting: | S40: =Barangays!GV5 -> #REF! | T40: # Children with no date of birth data: | Z40: =Barangays!IF5 -> #REF!
A41: Total Number of Children 0-29 mos. old: | H41: =Barangays!GM5 -> #REF! | T41: # Children older than 59 months: | Z41: =Barangays!II5 -> #REF!
A42: Total Number of Children 30-59 mos. old: | H42: =Barangays!GN5 -> #REF! | T42: # Children with length/height but no weight: | Z42: =Barangays!IC5 -> #REF!
A43: Total Number of Children 24-59 mos. old: | H43: =Barangays!GO5 -> #REF! | T43: # Children with weight but no length/height: | Z43: =Barangays!ID5 -> #REF!
A44: # Children 0-59 mos. w/ Edema: | H44: =Barangays!GP5 -> #REF! | T44: =IF(Barangays!$X$6 = "Weight + Length/Height", "", "# Children with no MUAC:") -> #REF! | Z44: =IF(Barangays!$X$6 = "Weight + Length/Height", "", Barangays!IJ5) -> #REF!
...
